{"trial_id": "1", "hyperparameters": {"space": [{"class_name": "Int", "config": {"name": "units", "default": null, "conditions": [], "min_value": 30, "max_value": 400, "step": 50, "sampling": "linear"}}], "values": {"units": 30}}, "metrics": {"metrics": {}}, "score": null, "best_step": 0, "status": "FAILED", "message": "Traceback (most recent call last):\n  File \"/Users/rebeccalilyverghese/opt/anaconda3/lib/python3.8/site-packages/keras_tuner/engine/base_tuner.py\", line 270, in _try_run_and_update_trial\n    self._run_and_update_trial(trial, *fit_args, **fit_kwargs)\n  File \"/Users/rebeccalilyverghese/opt/anaconda3/lib/python3.8/site-packages/keras_tuner/engine/base_tuner.py\", line 235, in _run_and_update_trial\n    results = self.run_trial(trial, *fit_args, **fit_kwargs)\n  File \"/Users/rebeccalilyverghese/opt/anaconda3/lib/python3.8/site-packages/keras_tuner/engine/tuner.py\", line 287, in run_trial\n    obj_value = self._build_and_fit_model(trial, *args, **copied_kwargs)\n  File \"/Users/rebeccalilyverghese/opt/anaconda3/lib/python3.8/site-packages/keras_tuner/engine/tuner.py\", line 214, in _build_and_fit_model\n    results = self.hypermodel.fit(hp, model, *args, **kwargs)\n  File \"/Users/rebeccalilyverghese/opt/anaconda3/lib/python3.8/site-packages/keras_tuner/engine/hypermodel.py\", line 144, in fit\n    return model.fit(*args, **kwargs)\n  File \"/Users/rebeccalilyverghese/opt/anaconda3/lib/python3.8/site-packages/keras/utils/traceback_utils.py\", line 67, in error_handler\n    raise e.with_traceback(filtered_tb) from None\n  File \"/var/folders/wb/sn8gsb7j749cp49ywxw15sg80000gn/T/__autograph_generated_file50ogc7mr.py\", line 15, in tf__train_function\n    retval_ = ag__.converted_call(ag__.ld(step_function), (ag__.ld(self), ag__.ld(iterator)), None, fscope)\nValueError: in user code:\n\n    File \"/Users/rebeccalilyverghese/opt/anaconda3/lib/python3.8/site-packages/keras/engine/training.py\", line 1051, in train_function  *\n        return step_function(self, iterator)\n    File \"/Users/rebeccalilyverghese/opt/anaconda3/lib/python3.8/site-packages/keras/engine/training.py\", line 1040, in step_function  **\n        outputs = model.distribute_strategy.run(run_step, args=(data,))\n    File \"/Users/rebeccalilyverghese/opt/anaconda3/lib/python3.8/site-packages/keras/engine/training.py\", line 1030, in run_step  **\n        outputs = model.train_step(data)\n    File \"/Users/rebeccalilyverghese/opt/anaconda3/lib/python3.8/site-packages/keras/engine/training.py\", line 890, in train_step\n        loss = self.compute_loss(x, y, y_pred, sample_weight)\n    File \"/Users/rebeccalilyverghese/opt/anaconda3/lib/python3.8/site-packages/keras/engine/training.py\", line 948, in compute_loss\n        return self.compiled_loss(\n    File \"/Users/rebeccalilyverghese/opt/anaconda3/lib/python3.8/site-packages/keras/engine/compile_utils.py\", line 184, in __call__\n        self.build(y_pred)\n    File \"/Users/rebeccalilyverghese/opt/anaconda3/lib/python3.8/site-packages/keras/engine/compile_utils.py\", line 133, in build\n        self._losses = tf.nest.map_structure(self._get_loss_object, self._losses)\n    File \"/Users/rebeccalilyverghese/opt/anaconda3/lib/python3.8/site-packages/keras/engine/compile_utils.py\", line 272, in _get_loss_object\n        loss = losses_mod.get(loss)\n    File \"/Users/rebeccalilyverghese/opt/anaconda3/lib/python3.8/site-packages/keras/losses.py\", line 2367, in get\n        return deserialize(identifier)\n    File \"/Users/rebeccalilyverghese/opt/anaconda3/lib/python3.8/site-packages/keras/losses.py\", line 2322, in deserialize\n        return deserialize_keras_object(\n    File \"/Users/rebeccalilyverghese/opt/anaconda3/lib/python3.8/site-packages/keras/utils/generic_utils.py\", line 709, in deserialize_keras_object\n        raise ValueError(\n\n    ValueError: Unknown loss function: witness_loss_fn. Please ensure this object is passed to the `custom_objects` argument. See https://www.tensorflow.org/guide/keras/save_and_serialize#registering_the_custom_object for details.\n\n"}